Workbook
Name _Don1: 'Variable Management'!$B$34
Name _Don2: 'Variable Management'!$B$49
Name Acs: 'Variable Management'!$B$223
Name Acs_Ch2: 'Variable Management'!$D$223
Name Adc: 'Stability Calculations'!$U$3
Name AEA: 'Variable Management'!$B$221
Name Afb: 'Variable Management'!$B$222
Name Afb_Ch2: 'Variable Management'!$D$222
Name Afbr: 'Stability Calculations'!$Q$6
Name Am: 'Variable Management'!$B$225
Name Am_buck: 'Variable Management'!$B$224
Name Am_buck_Ch2: 'Variable Management'!$D$224
Name Am_Ch2: 'Variable Management'!$D$225
Name Attn_req: 'Variable Management'!$B$284
Name BODE_PLOT_Ch1: 'Bode Plot Management'!$B$5
Name BODE_PLOT_Ch2: 'Bode Plot Management'!$B$8
Name BODE_PLOT_TYPE: 'Variable Management'!$AA$10
Name Buck_CS_threshold: 'Variable Management'!$B$85
Name Buck_CS_threshold_max: 'Variable Management'!$B$86
Name Buck_CS_threshold_min: 'Variable Management'!$B$84
Name Cb: 'Variable Management'!$B$194
Name Cbw: 'Variable Management'!$B$219
Name Cby: 'Variable Management'!$B$193
Name Cc1ea: 'Variable Management'!$B$242
Name Cc1ea_u: 'Variable Management'!$B$248
Name Cc2ea: 'Variable Management'!$B$243
Name Cc2ea_u: 'Variable Management'!$B$249
Name Cc3ea: 'Variable Management'!$D$242
Name Cc3ea_u: 'Variable Management'!$D$248
Name Cc4ea: 'Variable Management'!$D$243
Name Cc4ea_u: 'Variable Management'!$D$249
Name Ccomp_AEF: 'Variable Management'!$D$297
Name Cdamp_AEFstd: 'Standard Value Calculator'!$N$4
Name Cdamp_PassiveStd: 'Standard Value Calculator'!$L$4
Name CdampCom: 'Input Filter Calculations'!$AE$5
Name CdampPssv: 'Input Filter Calculations'!$M$5
Name CdampSel: 'Variable Management'!$D$295
Name Cdither: 'Variable Management'!$B$193
Name Cdither_init: 'Variable Management'!$B$192
Name Cfb: 'Variable Management'!$B$261
Name Cff: 'Variable Management'!$B$260
Name CfilterPssv: 'Input Filter Calculations'!$M$4
Name Ch2_VOUT: 'Variable Management'!$O$16
Name Cin: 'Variable Management'!$B$150
Name Cin_PassiveStd: 'Standard Value Calculator'!$K$4
Name CinEsrMax: 'Variable Management'!$B$154
Name Cinj_AEF: 'Variable Management'!$B$293
Name Cinj_AEFstd: 'Standard Value Calculator'!$M$4
Name CinjCom: 'Input Filter Calculations'!$AE$4
Name CinjSel: 'Variable Management'!$D$293
Name Cinmin: 'Variable Management'!$B$147
Name COMP_TYPE: 'Variable Management'!$AA$21
Name Core_Loss_Ch1: 'Variable Management'!$B$73
Name Coss_Q1: 'Variable Management'!$B$336
Name Coss_Q2: 'Variable Management'!$D$336
Name Cout: 'Variable Management'!$B$122
Name Cout_ESR: 'Variable Management'!$B$126
Name Cout_min: 'Variable Management'!$B$120
Name Cout2: 'Variable Management'!$D$122
Name Cout2_ESR: 'Variable Management'!$D$126

Sheet Design Regulator
A1: LM(2)5148/-Q1 Synchronous Buck Controller Design Tool
N2: http://www.ti.com/product/lm5175
A3: About | C3: xx | F3: = Input Box | N3: TERMS OF USE
A5: Step 1: Operating Specifications
D6: Input Voltage – Min, VIN(min) | E6: 10 | F6: V
D7: Input Voltage – Nom, VIN(nom) | E7: 12 | F7: V
D8: Input Voltage – Max, VIN(max) | E8: 18 | F8: V
D9: Output Voltage, VOUT | E9: 5 | F9: V
D10: Full Load Output Current, IOUT | E10: 8 | F10: A
D11: Switching Frequency, FSW | E11: 2100 | F11: kHz
D12: Frequency Set Resistor, RT | E12: ='Variable Management'!C443 | F12: kΩ
D13: Ambient Temperature, TA | E13: 25 | F13: °C
A15: Step 2: Current Sense Resistor
D16: Required IOCP Setpoint at VIN(nom) | E16: 7 | F16: A
D17: Recommended Shunt Resistance | E17: =Rs_ideal*1000 | F17: mΩ
D18: Shunt Resistance, RS | E18: 4.6 | F18: mΩ
D19: Min Inductor Sat Current, ILO(SAT) | E19: ='Variable Management'!B95 | F19: A
D20: Max Power Loss in Shunt | E20: ='Variable Management'!B105 | F20: W
D21: VIN(min) | E21: ='Variable Management'!B97 | F21: A
C22: IOUT(typ) at OCP Inception: | D22: VIN(nom) | E22: ='Variable Management'!B98 | F22: A
D23: VIN(max) | E23: ='Variable Management'!B99 | F23: A
A25: Step 3: Buck Inductance
D26: Inductance for Ideal Slope Comp | E26: =Lopt*1000000 | F26: µH
D27: Inductance, LO | E27: 2.2 | F27: µH
D28: Inductor DCR | E28: 3.5 | F28: mΩ
D29: DIL as a % at VIN(nom) | E29: ='Variable Management'!B68*100 | F29: %
D30: Estimate Core Loss at VIN(nom) | E30: 0.2 | F30: W
A32: Step 4: Output Capacitors
D33: Output Voltage Ripple Spec | E33: 50 | F33: mVPK=PK
D34: Minimum Output Capacitance | E34: ='Variable Management'!B121 | F34: µF
D35: Output Capacitance (derated), COUT | E35: 200 | F35: µF | K35: =CHOOSE(SCH_MODE, "", "** For Single-Output Operation in 2-Phase Mode, tie MODE to VDDA and use FB1 to set VOUT **", "** For Single-Output Operation in 3-Phase Mode, tie both MODE pins to VDDA. Use FB1 of master IC to set VOUT. Connect FB2 of master IC to AGND. Connect FB2 of slave IC to VDDA to configure it as a slave **", "** For Single-Output Operation in 4-Phase Mode, tie both MODE pins to VDDA. Use FB1 of master IC to set VOUT. Connect FB2 of master IC to AGND. Connect FB2 of slave IC to VDDA to configure it as a slave **")
D36: Maximum Permitted ESR | E36: ='Variable Management'!B125 | F36: mΩ
D37: Output Capacitor ESR | E37: 1 | F37: mΩ | K37: =CHOOSE(SCH_MODE, "", "** Tie VCCX to GND if not used **", "** Slave controller (CNTRL2) not shown **","** Slave controller (CNTRL2) not shown **") | P37: =IF(SCH_MODE=1, "** Tie VCCX to GND if not used **", "")
D38: Resulting Output Voltage Ripple (max) | E38: ='Variable Management'!B127*1000 | F38: mVPK-PK | K38: =IF(OR(SCH_MODE=3, SCH_MODE=4),"** Tie VCCX to GND if not used **", "")
D39: Output Capacitor RMS Current (max) | E39: ='Variable Management'!B114 | F39: ARMS
A41: Step 5: Input Capacitors
D42: Input Voltage Ripple Spec | E42: 400 | F42: mVPK-PK
D43: Minimum Input Capacitance | E43: ='Variable Management'!B148 | F43: µF
D44: Input Capacitance (derated), CIN | E44: 30 | F44: µF
D45: Maximum Permitted ESR | E45: ='Variable Management'!B155 | F45: mΩ
...

Sheet Input Filters
A1: LM(2)5149-Q1 Synchronous Buck Controller Design Tool
O2: http://www.ti.com/product/lm5175
A3: About | C3: xx | F3: = Input Box | O3: TERMS OF USE
E7: AEF | M7: Passive
B9: Design tab - LAEF | C9: ='Design Regulator'!E49 & " µH" | F9: LAEF | G9: 1 | H9: µH | J9: Suggested LIN Inductor | K9: 0.1-10 | L9: µH | N9: Chosen LIN | O9: 0.68 | P9: µH
B10: Design tab - CINJ | C10: ='Design Regulator'!#REF! & " µF" | F10: CINJ | G10: 1 | H10: µF | J10: Suggested CF | K10: 0.1-10 | L10: µF | N10: Chosen CF | O10: 0.47 | P10: µF
B11: Design tab - CDAMP | C11: ='Design Regulator'!#REF! & " µF" | F11: CDAMP | G11: 1 | H11: µF | J11: Suggested CDAMP | K11: 1-10 | L11: µF | N11: Chosen CDAMP | O11: 1 | P11: µF
B12: Design tab - RDAMP | C12: ='Design Regulator'!#REF! & " Ω" | F12: RDAMP | G12: 10 | H12: Ω | J12: Suggested RDAMP | K12: =Rdamp_PassiveStd | L12: Ω | N12: Chosen RDAMP | O12: 0.35 | P12: Ω
C14: VIN Ripple at Fsw | F14: =VinRipple_dBuV | G14: dBµV | H14: VIN Ripple | I14: =VinRipple_dBuV | J14: dBµV
D16: AEF Attenuation at Fsw | E16: =-'Input Filter Calculations'!AM97 | F16: dB | L16: Passive Attenuation at Fsw | M16: =-'Input Filter Calculations'!AA97 | N16: dB
D17: AEF EMI at Fsw | E17: =VinRipple_dBuV-E16 | F17: dB-µV | L17: Passive EMI at Fsw | M17: =VinRipple_dBuV-M16 | N17: dB-µV

Sheet Design Input Filter
A1: LM5149-Q1 Synchronous Buck Controller Design Tool
O2: http://www.ti.com/product/lm5175
A3: About | C3: xx | F3: = Input Box | O3: TERMS OF USE
B7: Choose Filter
B8: Suggested Inductor | C8: =CHOOSE(INFILTER_TYPE,"","0.01-1","0.1-10") | D8: µH | F8: Chosen Inductor | G8: 1 | H8: µH
B9: =CHOOSE(INFILTER_TYPE,"","Suggested Cinj","Suggested Cf") | C9: =CHOOSE(INFILTER_TYPE,"",'Standard Value Calculator'!S24,'Standard Value Calculator'!S23) | D9: µF | F9: =CHOOSE(INFILTER_TYPE,"","Chosen Cinj","Chosen Cf") | G9: 0.068 | H9: µF
B10: Suggested Cdamp | C10: =CHOOSE(INFILTER_TYPE,"",CHOOSE(OSC,"DNP",'Standard Value Calculator'!S25),'Standard Value Calculator'!S28) | D10: µF | F10: Chosen Cdamp | G10: 0.033 | H10: µF
B11: Suggested Rdamp | C11: =CHOOSE(INFILTER_TYPE,"",'Standard Value Calculator'!S26,Rdamp_PassiveStd) | D11: Ω | F11: Chosen Rdamp | G11: 43.2 | H11: Ω
F12: Filter Attenuation | G12: =-'Variable Management'!B303 | H12: dB
F13: VIN Ripple | G13: =VinRipple_dBuV | H13: dB-µV
F14: Fsw Conducted EMC | G14: ='Variable Management'!B304 | H14: dB-µV

Sheet BOM & Schematic
I33: =IF(OR(SCH_MODE=3, SCH_MODE=4),"** Tie VCCX to GND if not used **", "")
A34: ** Tie PFM to VDDA for PFM, AGND for FPWM **
A35: ** Tie VCCX to GND if not used **
A36: ="Vin = "&VIN_min&"V to "&VIN_max&"V, Vout = "& Vout &"V, Iout = " &Iout & "A, Fsw = " & Fsw/1000 &"kHz, Current Limit = "&ROUNDUP(Ilimit_DC,0)&"A"
A37: High-Efficiency Synchronous Buck Regulator BOM
A38: Count | B38: Ref Des | C38: Value | D38: Description | H38: Size | I38: Part Number | J38: MFR
A39: 1 | B39: CBOOT | C39: 0.1 | D39: =C39 | H39: 0603 | I39: Std | J39: Std
A40: 1 | B40: CCOMP | C40: ='Design Regulator'!D72 | D40: =C40 | H40: 0603 | I40: Std | J40: Std
A41: 1 | B41: CHF | C41: ='Design Regulator'!D73 | D41: =C41 | H41: 0603 | I41: Std | J41: Std
A42: =ROUNDUP('Design Regulator'!E44/10,0) | B42: CIN | C42: 10 | D42: =C42 | H42: 1210 | I42: Std | J42: Std
A43: =ROUNDUP('Design Regulator'!E35/47,0) | B43: COUT | C43: 47 | D43: =C43 | H43: 1210 | I43: Std | J43: Std
A44: 2 | B44: CVCC, CVCCX | C44: 2.2 | D44: =C44 | H44: 0603 | I44: Std | J44: Std
A45: 1 | B45: CVDDA | C45: 0.47 | D45: =C45 | H45: 0603 | I45: Std | J45: Std
A46: 1 | B46: LO | C46: ='Design Regulator'!E27 | D46: ="Inductor, "&Lf*1000000&"µH, "&Rdcr*1000&"mΩ, >"&ROUNDUP(Ilimit_DC*1.1,0)&"A" | H46: - | I46: - | J46: Various
A47: 2 | B47: Q1, Q2 | C47: See description | D47: ='Design Regulator'!E82 | H47: Std | I47: ='Design Regulator'!E80 | J47: -
A48: 1 | B48: RCOMP | C48: ='Design Regulator'!D71 | D48: =C48 | H48: 0603 | I48: Std | J48: Std
A49: 1 | B49: RS | C49: =Rs*1000 | D49: =C49 | H49: 0508 | I49: Std | J49: Std
A50: 1 | B50: RT | C50: ='Design Regulator'!E12 | D50: =C50 | H50: 0603 | I50: Std | J50: Std
A51: 1 | B51: RFB1 | C51: ='Design Regulator'!E65 | D51: =C51 | H51: 0603 | I51: Std | J51: Std
A52: 1 | B52: RFB2 | C52: ='Design Regulator'!E66 | D52: =C52 | H52: 0603 | I52: Std | J52: Std
A53: 1 | B53: RPG | C53: 100 | D53: =C53 | H53: 0603 | I53: Std | J53: Std
A54: 1 | B54: RCS | C54: 100 | D54: =C54 | H54: 0603 | I54: Std | J54: Std
A55: 1 | B55: RVIN | C55: 2.2 | D55: =C55 | H55: 0603 | I55: Std | J55: Std
A56: 1 | B56: U1 | C56: ='Variable Management'!P29 | D56: =CHOOSE(VARIANT, "IC, LM5148, Synchronous Buck PWM Controller, 3.5V–80V Input", "IC, LM5148-Q1, Synchronous Buck PWM Controller, 3.5V–80V Input", "IC, LM25148, Synchronous Buck PWM Controller, 3.5V–42V Input", "IC, LM25148-Q1, Synchronous Buck PWM Controller, 3.5V–42V Input") | H56: VQFN-24 | I56: =CHOOSE(VARIANT, "LM5148RGYR", "LM5148QRGYRQ1", "LM25148RGYR", "LM25148QRGYRQ1") | J56: TI
A59: NOTES:
A60: ** Inductor saturation current should be higher than the peak inductor current at the OCP setpoint for all input voltages and operating temperatures **
A61: ** Effective input and output capacitances should be appropriately derated for applied voltage and temperature, particularly with ceramics **

Sheet EVM
A1: LM25149-Q1 Quickstart Design Tool
B6: LM25149-Q1EVM-2100 PCB Layout

Sheet Variable Management
A1: EXCEL Variables Names/Calculations
B2: Input from user =
B3: Output =
B4: Constant
A5: Variable Name | B5: Value | C5: STD Units | E5: Notes | I5: Iteration
A6: Step 1: Operational Specs
A7: VIN_min | B7: ='Design Regulator'!E6 | C7: V | D7: Minimum input voltage | I7: 1
A8: VIN_nom | B8: ='Design Regulator'!E7 | C8: V | D8: Nominal input voltage | K8: =CHOOSE(SCH_MODE, "Efficiency vs. IOUT (Ch1)", "Efficiency vs. IOUT - 2 Ph", "Efficiency vs. IOUT - 3 Ph", "Efficiency vs. IOUT - 4 Ph") | L8: 1 | N8: DRSS Enabled | O8: 1 | T8: Dual Outputs | U8: 1 | W8: FPWM | X8: 1 | Z8: =CHOOSE(SCH_MODE, "Bode Plot (Ch1)", "Bode Plot - 2 Ph", "Bode Plot - 3 Ph", "Bode Plot - 4 Ph") | AA8: 1
A9: VIN_max | B9: ='Design Regulator'!E8 | C9: V | D9: Maximum input voltage | K9: =IF(MODE=1, "Efficiency vs. IOUT (Ch2)", "N/A - Do Not Use") | L9: 2 | N9: DRSS Disabled | O9: 2 | T9: Single Output – 2 Phases | U9: 2 | W9: PFM | X9: 2 | Z9: =IF(MODE=1, "AEF Gain", "N/A - Do Not Use") | AA9: 2
K10: PLOT_TYPE | L10: 1 | N10: DRSS Yes/No | O10: 1 | P10: 1 = Yes, 2 = No | T10: Single Output – 3 Phases | U10: 3 | W10: FPWM/PFM | X10: 1 | Z10: BODE_PLOT_TYPE | AA10: 1
A11: Vout | B11: ='Design Regulator'!E9 | C11: V | D11: Output voltage - channel 1 | T11: Single Output – 4 Phases | U11: 4
A12: Iout | B12: ='Design Regulator'!E10 | C12: A | D12: Output current - channel 1 | I12: 1 | T12: Single/Dual Yes/No | U12: 1
I13: 1 | K13: Adjustable | L13: 1 | N13: 3.3V | O13: 1 | T13: MODE (Single/Dual), DUAL = 1, SINGLE = 2 | U13: =IF(U12=1, 1, 2) | W13: VCCX Connected | X13: 1
A14: Rout | B14: =Vout/Iout | C14: W | D14: Load resistance - Channel 1 | K14: 5V | L14: 2 | N14: 5V | O14: 2 | T14: SINGLE OUTPUT (1 = YES) | U14: =IF(U12=1, 2, 1) | W14: No External VCC | X14: 2
K15: 3.3V | L15: 3 | N15: Adjustable | O15: 3 | T15: Number of Phases | U15: =SCH_MODE | W15: Ext_VCC | X15: 1
A16: Pout | B16: =Vout*Iout | C16: W | D16: Output power | K16: 12V | L16: 4 | N16: Output Setting | O16: =IF(Vout2=3.3, 1, IF(Vout2=5, 2, 3))
K17: Output Voltage Setting | L17: =IF(Vout=3.3, 3, IF(Vout=5, 2, IF(Vout=12,4,1)))
A18: Efficiency | B18: 0.9 | D18: Estimate of efficiency
A19: Pin | B19: =Pout/Efficiency | C19: W | D19: Calculate input power assuming finite efficiency | Z19: Internal Compensation | AA19: 1
Z20: External Compensation | AA20: 2
A21: Iin_Vinmin | B21: =Pin/VIN_min | C21: A | L21: =Vout | Z21: COMP_TYPE | AA21: 2
A22: Iin_Vinnom | B22: =Pin/VIN_nom | C22: A | D22: Input currents at min, nom, max Vin | H22: =AND(OSC=1, OR(Fsw/1000>2530, Fsw/1000<1800))
A23: Iin_Vinmax | B23: =Pin/VIN_max | C23: A | H23: =AND(OSC=2, OR(Fsw/1000>500, Fsw/1000<300))
H24: =OR(H22,H23)
A25: OSC setting | B25: =CHOOSE(OSC, 2200, 440) | C25: kHz | K25: SetVout_IntComp_nAEF | L25: 1 | P25: LM5148 | Q25: 1 | W25: No Input Filter | X25: 1 | Z25: UVLO Divider | AA25: 1
A26: Fsw | B26: ='Design Regulator'!E11*1000 | C26: Hz | D26: Nominal switching frequency - determines RT resistor (SYNCIN must be 80-120% of this) | K26: SetVout_IntComp_AEF | L26: 2 | P26: LM5148-Q1 | Q26: 2 | W26: AEF Input Filter | X26: 2 | Z26: No UVLO Divider | AA26: 2
A27: RT resistor to AGND | B27: =((1000000000/Fsw)-53)/45+0.1 | C27: kΩ | K27: SetVout_ExtComp_nAEF | L27: 3 | P27: LM25148 | Q27: 3 | W27: Passive LC Filter | X27: 3 | Z27: UVLO_TYPE | AA27: 1
C28: kΩ | I28: 1 | K28: SetVout_ExtComp_AEF | L28: 4 | P28: LM25148-Q1 | Q28: 4 | W28: INFILTER_TYPE | X28: 1
A29: Tsw | B29: =1/Fsw | C29: sec | D29: Switching period | K29: AdjVout_IntComp_nAEF | L29: 5 | O29: VARIANT | P29: =CHOOSE(VARIANT, "LM5148", "LM5148-Q1", "LM25148", "LM25148-Q1") | Q29: 1
A30: Vref | B30: 0.8 | C30: V | D30: Reference voltage | K30: AdjVout_IntComp_AEF | L30: 6 | O30: VIN-MAX | P30: =CHOOSE(VARIANT, 80, 80, 42, 42) | Q30: V
A31: Rt | B31: ='Standard Value Calculator'!S12/1000 | C31: kΩ | D31: Frequency set resistor | F31: =IF(OR((Fsw=440000),(Fsw=2200000)),"N/A",Rfadj/1000) | K31: AdjVout_ExtComp_nAEF | L31: 7 | O31: VOUT-MAX | P31: =CHOOSE(VARIANT, 60, 60, 36, 36) | Q31: V
K32: AdjVout_ExtComp_AEF | L32: 8
A33: Step 2: Buck Inductor | B33: Channel 1 | K33: Schematic setting | L33: =(IF(OR(Vout=3.3,Vout=5,Vout=12),CHOOSE(COMP_TYPE,IF(INFILTER_TYPE=1,1,2),IF(INFILTER_TYPE=1,3,4)),CHOOSE(COMP_TYPE,IF(INFILTER_TYPE=1,5,6),IF(INFILTER_TYPE=1,7,8))))
A34: Don1 | B34: =Vout/VIN_nom | F34: Ideal Duty Cycle at VIN(nom)
A35: Doff1 | B35: =1-34:34 | F35: Ideal 1- Duty Cycle at VIN(nom)
A37: D_Vinmin | B37: =Vout/VIN_min
A38: D_Vinnom | B38: =Vout/VIN_nom
A39: D_Vinmax | B39: =Vout/VIN_max
A41: L_Vinnom | B41: =(VIN_nom-Vout)*D1_Vinnom/(Fsw*(Iout/Number_of_Phases)*0.3) | C41: H | F41: Calculated inductance for 35% ripple at VIN(nom)
A42: L_slopecomp | B42: =1000*Vout*Rs/22.72/Fsw | C42: H | F42: Calculated inductance based on one times inductor downslope
...

Sheet Schematic Management
N1: 3.3V or 5V fixed (FB1/2)
A2: =IF(MODE=1, CHOOSE(SCH_SETTING, "SCH_SetVout_IntComp_nAEF","SCH_SetVout_IntComp_AEF","SCH_SetVout_ExtComp_nAEF","SCH_SetVout_ExtComp_AEF","SCH_AdjVout_IntComp_nAEF","SCH_AdjVout_IntComp_AEF","SCH_AdjVout_ExtComp_nAEF","SCH_AdjVout_ExtComp_AEF")) | N2: With/without VOUT connected to VCCX

Sheet Stability Calculations
A2: Divider Network & EA Poles/Zeros | E2: Modulator | J2: Power Stage Poles/Zeros | M2: Complex Pole Pair | P2: Feedback natural frequencies | T2: Total System
B3: Afb1 | C3: =Afb | D3: V/V | E3: Acs | F3: =Acs | G3: A/V | H3: gm | I3: =gm | J3: z_ESR | K3: =Fesr | L3: Hz | M3: p3 | N3: =Fsw/2 | O3: Hz | P3: zterm1 | Q3: =((1/wffHz)+(1/wfftHz)) | T3: Adc | U3: =IF(VOUT_setting=1,Am*Afb*AEA,Am*AEA) | V3: V/V
B4: EA zero, z1 | C4: =Fz1_u | D4: Hz | E4: Am | F4: =Am | G4: V/V | J4: p_dom | K4: =Fp_dominant | L4: Hz | M4: pterm1 | N4: =Q*pole3 | P4: pterm3 | Q4: =((1/wfbtHz)+(1/wffHz)+(1/wfftHz)+(Afbr/wffHz)) | T4: Crossover | U4: =AI7 | V4: kHz
B5: EA pole, p1 | C5: =Fp1_u | D5: Hz | E5: Q | F5: =Q | M5: pterm2 | N5: =pole3^2 | P5: pterm4 | Q5: =1/(wffHz*wfbtHz) | T5: Phase Margin | U5: =AI9 | V5: °
B6: Aea | C6: =AEA | D6: V/V | E6: mc | F6: =mc | P6: Afbr | Q6: =Rfb1_/Rfb2_u | T6: radconv | U6: =180/Pi | AH6: XOVER SEARCH
B7: EA pole, p2 | C7: =Fp2_u | D7: Hz | E7: k | F7: =k | AH7: xover | AI7: =SUM(AH12:AH613)/1000
AH9: phase margin | AI9: =SUM(AI13:AI613)
A10: Freq (Hz) | C10: Power Stage | I10: Error Amplifier | O10: Feedback Gain | S10: Sampling Double Pole | U10: System Response | AB10: ERROR AMP Response | AE10: PLANT Response
C11: p_dom | E11: z_ESR | G11: z_RHP | I11: p1 | K11: z1 | M11: p2 | O11: z1 | Q11: p1p2 | S11: p3
C12: Gain(V/V) | D12: Phase(rad) | E12: Gain(V/V) | F12: Phase(rad) | G12: Gain(V/V) | H12: Phase(rad) | I12: Gain(V/V) | J12: Phase(rad) | K12: Gain(V/V) | L12: Phase(rad) | M12: Gain(V/V) | N12: Phase(rad) | O12: Gain(V/V) | P12: Phase(rad) | Q12: Gain(V/V) | R12: Phase(rad) | S12: Gain(V/V) | T12: Phase(rad) | U12: Gain (dB) | V12: Phase (°) | W12: Phase Margin (°) | Z12: Fsquare | AB12: Gain(dB) | AC12: Phase(Deg) | AE12: Gain(dB) | AF12: Phase(Deg)
A13: 1 | B13: =A13/1000 | C13: =SQRT(1+(A13/pole1)^2) | D13: =ATAN(A13/pole1) | E13: =SQRT(1+(A13/Zero1)^2) | F13: =ATAN(A13/Zero1) | G13: =IF(VIN_nom>Vout, 1, SQRT(1+(A13/z_RHP)^2)) | H13: =IF(VIN_nom>Vout, 0, -ATAN(A13/z_RHP)) | I13: =SQRT(1+(A13/Pole2)^2) | J13: =ATAN(A13/Pole2) | K13: =SQRT(1+(A13/Zero2)^2) | L13: =ATAN(A13/Zero2) | M13: =SQRT(1+(A13/pole4)^2) | N13: =ATAN(A13/pole4) | O13: =IF(VOUT_setting=1,1,SQRT(1+(A13*zterm1)^2)) | P13: =IF(VOUT_setting=1,0,ATAN(((A13*zterm1)))) | Q13: =IF(VOUT_setting=1,1,SQRT((1+Afbr-pterm4*(A13)^2)^2+(A13*$Q$4)^2)) | R13: =IF(VOUT_setting=1,0,ATAN(A13*$Q$4/(1+Afbr-$Q$5*(A13)^2))) | S13: =SQRT((1-(Z13/pterm2))^2+(A13/pterm1)^2) | T13: =IF((ATAN((A13/pterm1)/(1-A13^2/pterm2))>0),ATAN((A13/pterm1)/(1-A13^2/pterm2)),PI()+ATAN((A13/pterm1)/(1-A13^2/pterm2))) | U13: =20*LOG10(((E13*K13*G13*O13)/(C13*I13*S13*M13*Q13))*Adc) | V13: =((F13+L13+H13+P13)-(D13+J13+T13+N13+R13))*radconv | W13: =IF(V13>0,V13,V13+180) | Y13: =IF(U13<0,A13,1000000000) | Z13: =A13^2 | AB13: =20*LOG10((K13/(I13*M13))*AEA) | AC13: =(L13-(J13+N13))*radconv | AE13: =20*LOG10((E13*G13/(C13*S13))*Acs*Am) | AF13: =(F13+H13-(D13+T13))*radconv | AH13: =SUM((U14<0)*(U13>0))*A13 | AI13: =IF(AH13>0,W11,0)
A14: 1.0965 | B14: =A14/1000 | C14: =SQRT(1+(A14/pole1)^2) | D14: =ATAN(A14/pole1) | E14: =SQRT(1+(A14/Zero1)^2) | F14: =ATAN(A14/Zero1) | G14: =IF(VIN_nom>Vout, 1, SQRT(1+(A14/z_RHP)^2)) | H14: =IF(VIN_nom>Vout, 0, -ATAN(A14/z_RHP)) | I14: =SQRT(1+(A14/Pole2)^2) | J14: =ATAN(A14/Pole2) | K14: =SQRT(1+(A14/Zero2)^2) | L14: =ATAN(A14/Zero2) | M14: =SQRT(1+(A14/pole4)^2) | N14: =ATAN(A14/pole4) | O14: =IF(VOUT_setting=1,1,SQRT(1+(A14*zterm1)^2)) | P14: =IF(VOUT_setting=1,0,ATAN(((A14*zterm1)))) | Q14: =IF(VOUT_setting=1,1,SQRT((1+Afbr-pterm4*(A14)^2)^2+(A14*$Q$4)^2)) | R14: =IF(VOUT_setting=1,0,ATAN(A14*$Q$4/(1+Afbr-$Q$5*(A14)^2))) | S14: =SQRT((1-(Z14/pterm2))^2+(A14/pterm1)^2) | T14: =IF((ATAN((A14/pterm1)/(1-A14^2/pterm2))>0),ATAN((A14/pterm1)/(1-A14^2/pterm2)),PI()+ATAN((A14/pterm1)/(1-A14^2/pterm2))) | U14: =20*LOG10(((E14*K14*G14*O14)/(C14*I14*S14*M14*Q14))*Adc) | V14: =((F14+L14+H14+P14)-(D14+J14+T14+N14+R14))*radconv | W14: =IF(V14>0,V14,V14+180) | Y14: =IF(U14<0,A14,1000000000) | Z14: =A14^2 | AB14: =20*LOG10((K14/(I14*M14))*AEA) | AC14: =(L14-(J14+N14))*radconv | AE14: =20*LOG10((E14*G14/(C14*S14))*Acs*Am) | AF14: =(F14+H14-(D14+T14))*radconv | AH14: =SUM((U15<0)*(U14>0))*A14 | AI14: =IF(AH14>0,W12,0)
A15: 1.2023 | B15: =A15/1000 | C15: =SQRT(1+(A15/pole1)^2) | D15: =ATAN(A15/pole1) | E15: =SQRT(1+(A15/Zero1)^2) | F15: =ATAN(A15/Zero1) | G15: =IF(VIN_nom>Vout, 1, SQRT(1+(A15/z_RHP)^2)) | H15: =IF(VIN_nom>Vout, 0, -ATAN(A15/z_RHP)) | I15: =SQRT(1+(A15/Pole2)^2) | J15: =ATAN(A15/Pole2) | K15: =SQRT(1+(A15/Zero2)^2) | L15: =ATAN(A15/Zero2) | M15: =SQRT(1+(A15/pole4)^2) | N15: =ATAN(A15/pole4) | O15: =IF(VOUT_setting=1,1,SQRT(1+(A15*zterm1)^2)) | P15: =IF(VOUT_setting=1,0,ATAN(((A15*zterm1)))) | Q15: =IF(VOUT_setting=1,1,SQRT((1+Afbr-$Q$5*(A15)^2)^2+(A15*$Q$4)^2)) | R15: =IF(VOUT_setting=1,0,ATAN(A15*$Q$4/(1+Afbr-$Q$5*(A15)^2))) | S15: =SQRT((1-(Z15/pterm2))^2+(A15/pterm1)^2) | T15: =IF((ATAN((A15/pterm1)/(1-A15^2/pterm2))>0),ATAN((A15/pterm1)/(1-A15^2/pterm2)),PI()+ATAN((A15/pterm1)/(1-A15^2/pterm2))) | U15: =20*LOG10(((E15*K15*G15*O15)/(C15*I15*S15*M15*Q15))*Adc) | V15: =((F15+L15+H15+P15)-(D15+J15+T15+N15+R15))*radconv | W15: =IF(V15>0,V15,V15+180) | Y15: =IF(U15<0,A15,1000000000) | Z15: =A15^2 | AB15: =20*LOG10((K15/(I15*M15))*AEA) | AC15: =(L15-(J15+N15))*radconv | AE15: =20*LOG10((E15*G15/(C15*S15))*Acs*Am) | AF15: =(F15+H15-(D15+T15))*radconv | AH15: =SUM((U16<0)*(U15>0))*A15 | AI15: =IF(AH15>0,W13,0)
A16: 1.3183 | B16: =A16/1000 | C16: =SQRT(1+(A16/pole1)^2) | D16: =ATAN(A16/pole1) | E16: =SQRT(1+(A16/Zero1)^2) | F16: =ATAN(A16/Zero1) | G16: =IF(VIN_nom>Vout, 1, SQRT(1+(A16/z_RHP)^2)) | H16: =IF(VIN_nom>Vout, 0, -ATAN(A16/z_RHP)) | I16: =SQRT(1+(A16/Pole2)^2) | J16: =ATAN(A16/Pole2) | K16: =SQRT(1+(A16/Zero2)^2) | L16: =ATAN(A16/Zero2) | M16: =SQRT(1+(A16/pole4)^2) | N16: =ATAN(A16/pole4) | O16: =IF(VOUT_setting=1,1,SQRT(1+(A16*zterm1)^2)) | P16: =IF(VOUT_setting=1,0,ATAN(((A16*zterm1)))) | Q16: =IF(VOUT_setting=1,1,SQRT((1+Afbr-$Q$5*(A16)^2)^2+(A16*$Q$4)^2)) | R16: =IF(VOUT_setting=1,0,ATAN(A16*$Q$4/(1+Afbr-$Q$5*(A16)^2))) | S16: =SQRT((1-(Z16/pterm2))^2+(A16/pterm1)^2) | T16: =IF((ATAN((A16/pterm1)/(1-A16^2/pterm2))>0),ATAN((A16/pterm1)/(1-A16^2/pterm2)),PI()+ATAN((A16/pterm1)/(1-A16^2/pterm2))) | U16: =20*LOG10(((E16*K16*G16*O16)/(C16*I16*S16*M16*Q16))*Adc) | V16: =((F16+L16+H16+P16)-(D16+J16+T16+N16+R16))*radconv | W16: =IF(V16>0,V16,V16+180) | Y16: =IF(U16<0,A16,1000000000) | Z16: =A16^2 | AB16: =20*LOG10((K16/(I16*M16))*AEA) | AC16: =(L16-(J16+N16))*radconv | AE16: =20*LOG10((E16*G16/(C16*S16))*Acs*Am) | AF16: =(F16+H16-(D16+T16))*radconv | AH16: =SUM((U17<0)*(U16>0))*A16 | AI16: =IF(AH16>0,W14,0)
A17: 1.4454 | B17: =A17/1000 | C17: =SQRT(1+(A17/pole1)^2) | D17: =ATAN(A17/pole1) | E17: =SQRT(1+(A17/Zero1)^2) | F17: =ATAN(A17/Zero1) | G17: =IF(VIN_nom>Vout, 1, SQRT(1+(A17/z_RHP)^2)) | H17: =IF(VIN_nom>Vout, 0, -ATAN(A17/z_RHP)) | I17: =SQRT(1+(A17/Pole2)^2) | J17: =ATAN(A17/Pole2) | K17: =SQRT(1+(A17/Zero2)^2) | L17: =ATAN(A17/Zero2) | M17: =SQRT(1+(A17/pole4)^2) | N17: =ATAN(A17/pole4) | O17: =IF(VOUT_setting=1,1,SQRT(1+(A17*zterm1)^2)) | P17: =IF(VOUT_setting=1,0,ATAN(((A17*zterm1)))) | Q17: =IF(VOUT_setting=1,1,SQRT((1+Afbr-$Q$5*(A17)^2)^2+(A17*$Q$4)^2)) | R17: =IF(VOUT_setting=1,0,ATAN(A17*$Q$4/(1+Afbr-$Q$5*(A17)^2))) | S17: =SQRT((1-(Z17/pterm2))^2+(A17/pterm1)^2) | T17: =IF((ATAN((A17/pterm1)/(1-A17^2/pterm2))>0),ATAN((A17/pterm1)/(1-A17^2/pterm2)),PI()+ATAN((A17/pterm1)/(1-A17^2/pterm2))) | U17: =20*LOG10(((E17*K17*G17*O17)/(C17*I17*S17*M17*Q17))*Adc) | V17: =((F17+L17+H17+P17)-(D17+J17+T17+N17+R17))*radconv | W17: =IF(V17>0,V17,V17+180) | Y17: =IF(U17<0,A17,1000000000) | Z17: =A17^2 | AB17: =20*LOG10((K17/(I17*M17))*AEA) | AC17: =(L17-(J17+N17))*radconv | AE17: =20*LOG10((E17*G17/(C17*S17))*Acs*Am) | AF17: =(F17+H17-(D17+T17))*radconv | AH17: =SUM((U18<0)*(U17>0))*A17 | AI17: =IF(AH17>0,W15,0)
A18: 1.5849 | B18: =A18/1000 | C18: =SQRT(1+(A18/pole1)^2) | D18: =ATAN(A18/pole1) | E18: =SQRT(1+(A18/Zero1)^2) | F18: =ATAN(A18/Zero1) | G18: =IF(VIN_nom>Vout, 1, SQRT(1+(A18/z_RHP)^2)) | H18: =IF(VIN_nom>Vout, 0, -ATAN(A18/z_RHP)) | I18: =SQRT(1+(A18/Pole2)^2) | J18: =ATAN(A18/Pole2) | K18: =SQRT(1+(A18/Zero2)^2) | L18: =ATAN(A18/Zero2) | M18: =SQRT(1+(A18/pole4)^2) | N18: =ATAN(A18/pole4) | O18: =IF(VOUT_setting=1,1,SQRT(1+(A18*zterm1)^2)) | P18: =IF(VOUT_setting=1,0,ATAN(((A18*zterm1)))) | Q18: =IF(VOUT_setting=1,1,SQRT((1+Afbr-$Q$5*(A18)^2)^2+(A18*$Q$4)^2)) | R18: =IF(VOUT_setting=1,0,ATAN(A18*$Q$4/(1+Afbr-$Q$5*(A18)^2))) | S18: =SQRT((1-(Z18/pterm2))^2+(A18/pterm1)^2) | T18: =IF((ATAN((A18/pterm1)/(1-A18^2/pterm2))>0),ATAN((A18/pterm1)/(1-A18^2/pterm2)),PI()+ATAN((A18/pterm1)/(1-A18^2/pterm2))) | U18: =20*LOG10(((E18*K18*G18*O18)/(C18*I18*S18*M18*Q18))*Adc) | V18: =((F18+L18+H18+P18)-(D18+J18+T18+N18+R18))*radconv | W18: =IF(V18>0,V18,V18+180) | Y18: =IF(U18<0,A18,1000000000) | Z18: =A18^2 | AB18: =20*LOG10((K18/(I18*M18))*AEA) | AC18: =(L18-(J18+N18))*radconv | AE18: =20*LOG10((E18*G18/(C18*S18))*Acs*Am) | AF18: =(F18+H18-(D18+T18))*radconv | AH18: =SUM((U19<0)*(U18>0))*A18 | AI18: =IF(AH18>0,W16,0)
A19: 1.7378 | B19: =A19/1000 | C19: =SQRT(1+(A19/pole1)^2) | D19: =ATAN(A19/pole1) | E19: =SQRT(1+(A19/Zero1)^2) | F19: =ATAN(A19/Zero1) | G19: =IF(VIN_nom>Vout, 1, SQRT(1+(A19/z_RHP)^2)) | H19: =IF(VIN_nom>Vout, 0, -ATAN(A19/z_RHP)) | I19: =SQRT(1+(A19/Pole2)^2) | J19: =ATAN(A19/Pole2) | K19: =SQRT(1+(A19/Zero2)^2) | L19: =ATAN(A19/Zero2) | M19: =SQRT(1+(A19/pole4)^2) | N19: =ATAN(A19/pole4) | O19: =IF(VOUT_setting=1,1,SQRT(1+(A19*zterm1)^2)) | P19: =IF(VOUT_setting=1,0,ATAN(((A19*zterm1)))) | Q19: =IF(VOUT_setting=1,1,SQRT((1+Afbr-$Q$5*(A19)^2)^2+(A19*$Q$4)^2)) | R19: =IF(VOUT_setting=1,0,ATAN(A19*$Q$4/(1+Afbr-$Q$5*(A19)^2))) | S19: =SQRT((1-(Z19/pterm2))^2+(A19/pterm1)^2) | T19: =IF((ATAN((A19/pterm1)/(1-A19^2/pterm2))>0),ATAN((A19/pterm1)/(1-A19^2/pterm2)),PI()+ATAN((A19/pterm1)/(1-A19^2/pterm2))) | U19: =20*LOG10(((E19*K19*G19*O19)/(C19*I19*S19*M19*Q19))*Adc) | V19: =((F19+L19+H19+P19)-(D19+J19+T19+N19+R19))*radconv | W19: =IF(V19>0,V19,V19+180) | Y19: =IF(U19<0,A19,1000000000) | Z19: =A19^2 | AB19: =20*LOG10((K19/(I19*M19))*AEA) | AC19: =(L19-(J19+N19))*radconv | AE19: =20*LOG10((E19*G19/(C19*S19))*Acs*Am) | AF19: =(F19+H19-(D19+T19))*radconv | AH19: =SUM((U20<0)*(U19>0))*A19 | AI19: =IF(AH19>0,W17,0)
A20: 1.9055 | B20: =A20/1000 | C20: =SQRT(1+(A20/pole1)^2) | D20: =ATAN(A20/pole1) | E20: =SQRT(1+(A20/Zero1)^2) | F20: =ATAN(A20/Zero1) | G20: =IF(VIN_nom>Vout, 1, SQRT(1+(A20/z_RHP)^2)) | H20: =IF(VIN_nom>Vout, 0, -ATAN(A20/z_RHP)) | I20: =SQRT(1+(A20/Pole2)^2) | J20: =ATAN(A20/Pole2) | K20: =SQRT(1+(A20/Zero2)^2) | L20: =ATAN(A20/Zero2) | M20: =SQRT(1+(A20/pole4)^2) | N20: =ATAN(A20/pole4) | O20: =IF(VOUT_setting=1,1,SQRT(1+(A20*zterm1)^2)) | P20: =IF(VOUT_setting=1,0,ATAN(((A20*zterm1)))) | Q20: =IF(VOUT_setting=1,1,SQRT((1+Afbr-$Q$5*(A20)^2)^2+(A20*$Q$4)^2)) | R20: =IF(VOUT_setting=1,0,ATAN(A20*$Q$4/(1+Afbr-$Q$5*(A20)^2))) | S20: =SQRT((1-(Z20/pterm2))^2+(A20/pterm1)^2) | T20: =IF((ATAN((A20/pterm1)/(1-A20^2/pterm2))>0),ATAN((A20/pterm1)/(1-A20^2/pterm2)),PI()+ATAN((A20/pterm1)/(1-A20^2/pterm2))) | U20: =20*LOG10(((E20*K20*G20*O20)/(C20*I20*S20*M20*Q20))*Adc) | V20: =((F20+L20+H20+P20)-(D20+J20+T20+N20+R20))*radconv | W20: =IF(V20>0,V20,V20+180) | Y20: =IF(U20<0,A20,1000000000) | Z20: =A20^2 | AB20: =20*LOG10((K20/(I20*M20))*AEA) | AC20: =(L20-(J20+N20))*radconv | AE20: =20*LOG10((E20*G20/(C20*S20))*Acs*Am) | AF20: =(F20+H20-(D20+T20))*radconv | AH20: =SUM((U21<0)*(U20>0))*A20 | AI20: =IF(AH20>0,W18,0)
A21: 2.0893 | B21: =A21/1000 | C21: =SQRT(1+(A21/pole1)^2) | D21: =ATAN(A21/pole1) | E21: =SQRT(1+(A21/Zero1)^2) | F21: =ATAN(A21/Zero1) | G21: =IF(VIN_nom>Vout, 1, SQRT(1+(A21/z_RHP)^2)) | H21: =IF(VIN_nom>Vout, 0, -ATAN(A21/z_RHP)) | I21: =SQRT(1+(A21/Pole2)^2) | J21: =ATAN(A21/Pole2) | K21: =SQRT(1+(A21/Zero2)^2) | L21: =ATAN(A21/Zero2) | M21: =SQRT(1+(A21/pole4)^2) | N21: =ATAN(A21/pole4) | O21: =IF(VOUT_setting=1,1,SQRT(1+(A21*zterm1)^2)) | P21: =IF(VOUT_setting=1,0,ATAN(((A21*zterm1)))) | Q21: =IF(VOUT_setting=1,1,SQRT((1+Afbr-$Q$5*(A21)^2)^2+(A21*$Q$4)^2)) | R21: =IF(VOUT_setting=1,0,ATAN(A21*$Q$4/(1+Afbr-$Q$5*(A21)^2))) | S21: =SQRT((1-(Z21/pterm2))^2+(A21/pterm1)^2) | T21: =IF((ATAN((A21/pterm1)/(1-A21^2/pterm2))>0),ATAN((A21/pterm1)/(1-A21^2/pterm2)),PI()+ATAN((A21/pterm1)/(1-A21^2/pterm2))) | U21: =20*LOG10(((E21*K21*G21*O21)/(C21*I21*S21*M21*Q21))*Adc) | V21: =((F21+L21+H21+P21)-(D21+J21+T21+N21+R21))*radconv | W21: =IF(V21>0,V21,V21+180) | Y21: =IF(U21<0,A21,1000000000) | Z21: =A21^2 | AB21: =20*LOG10((K21/(I21*M21))*AEA) | AC21: =(L21-(J21+N21))*radconv | AE21: =20*LOG10((E21*G21/(C21*S21))*Acs*Am) | AF21: =(F21+H21-(D21+T21))*radconv | AH21: =SUM((U22<0)*(U21>0))*A21 | AI21: =IF(AH21>0,W19,0)
A22: 2.2909 | B22: =A22/1000 | C22: =SQRT(1+(A22/pole1)^2) | D22: =ATAN(A22/pole1) | E22: =SQRT(1+(A22/Zero1)^2) | F22: =ATAN(A22/Zero1) | G22: =IF(VIN_nom>Vout, 1, SQRT(1+(A22/z_RHP)^2)) | H22: =IF(VIN_nom>Vout, 0, -ATAN(A22/z_RHP)) | I22: =SQRT(1+(A22/Pole2)^2) | J22: =ATAN(A22/Pole2) | K22: =SQRT(1+(A22/Zero2)^2) | L22: =ATAN(A22/Zero2) | M22: =SQRT(1+(A22/pole4)^2) | N22: =ATAN(A22/pole4) | O22: =IF(VOUT_setting=1,1,SQRT(1+(A22*zterm1)^2)) | P22: =IF(VOUT_setting=1,0,ATAN(((A22*zterm1)))) | Q22: =IF(VOUT_setting=1,1,SQRT((1+Afbr-$Q$5*(A22)^2)^2+(A22*$Q$4)^2)) | R22: =IF(VOUT_setting=1,0,ATAN(A22*$Q$4/(1+Afbr-$Q$5*(A22)^2))) | S22: =SQRT((1-(Z22/pterm2))^2+(A22/pterm1)^2) | T22: =IF((ATAN((A22/pterm1)/(1-A22^2/pterm2))>0),ATAN((A22/pterm1)/(1-A22^2/pterm2)),PI()+ATAN((A22/pterm1)/(1-A22^2/pterm2))) | U22: =20*LOG10(((E22*K22*G22*O22)/(C22*I22*S22*M22*Q22))*Adc) | V22: =((F22+L22+H22+P22)-(D22+J22+T22+N22+R22))*radconv | W22: =IF(V22>0,V22,V22+180) | Y22: =IF(U22<0,A22,1000000000) | Z22: =A22^2 | AB22: =20*LOG10((K22/(I22*M22))*AEA) | AC22: =(L22-(J22+N22))*radconv | AE22: =20*LOG10((E22*G22/(C22*S22))*Acs*Am) | AF22: =(F22+H22-(D22+T22))*radconv | AH22: =SUM((U23<0)*(U22>0))*A22 | AI22: =IF(AH22>0,W20,0)
A23: 2.5119 | B23: =A23/1000 | C23: =SQRT(1+(A23/pole1)^2) | D23: =ATAN(A23/pole1) | E23: =SQRT(1+(A23/Zero1)^2) | F23: =ATAN(A23/Zero1) | G23: =IF(VIN_nom>Vout, 1, SQRT(1+(A23/z_RHP)^2)) | H23: =IF(VIN_nom>Vout, 0, -ATAN(A23/z_RHP)) | I23: =SQRT(1+(A23/Pole2)^2) | J23: =ATAN(A23/Pole2) | K23: =SQRT(1+(A23/Zero2)^2) | L23: =ATAN(A23/Zero2) | M23: =SQRT(1+(A23/pole4)^2) | N23: =ATAN(A23/pole4) | O23: =IF(VOUT_setting=1,1,SQRT(1+(A23*zterm1)^2)) | P23: =IF(VOUT_setting=1,0,ATAN(((A23*zterm1)))) | Q23: =IF(VOUT_setting=1,1,SQRT((1+Afbr-$Q$5*(A23)^2)^2+(A23*$Q$4)^2)) | R23: =IF(VOUT_setting=1,0,ATAN(A23*$Q$4/(1+Afbr-$Q$5*(A23)^2))) | S23: =SQRT((1-(Z23/pterm2))^2+(A23/pterm1)^2) | T23: =IF((ATAN((A23/pterm1)/(1-A23^2/pterm2))>0),ATAN((A23/pterm1)/(1-A23^2/pterm2)),PI()+ATAN((A23/pterm1)/(1-A23^2/pterm2))) | U23: =20*LOG10(((E23*K23*G23*O23)/(C23*I23*S23*M23*Q23))*Adc) | V23: =((F23+L23+H23+P23)-(D23+J23+T23+N23+R23))*radconv | W23: =IF(V23>0,V23,V23+180) | Y23: =IF(U23<0,A23,1000000000) | Z23: =A23^2 | AB23: =20*LOG10((K23/(I23*M23))*AEA) | AC23: =(L23-(J23+N23))*radconv | AE23: =20*LOG10((E23*G23/(C23*S23))*Acs*Am) | AF23: =(F23+H23-(D23+T23))*radconv | AH23: =SUM((U24<0)*(U23>0))*A23 | AI23: =IF(AH23>0,W21,0)
A24: 2.7542 | B24: =A24/1000 | C24: =SQRT(1+(A24/pole1)^2) | D24: =ATAN(A24/pole1) | E24: =SQRT(1+(A24/Zero1)^2) | F24: =ATAN(A24/Zero1) | G24: =IF(VIN_nom>Vout, 1, SQRT(1+(A24/z_RHP)^2)) | H24: =IF(VIN_nom>Vout, 0, -ATAN(A24/z_RHP)) | I24: =SQRT(1+(A24/Pole2)^2) | J24: =ATAN(A24/Pole2) | K24: =SQRT(1+(A24/Zero2)^2) | L24: =ATAN(A24/Zero2) | M24: =SQRT(1+(A24/pole4)^2) | N24: =ATAN(A24/pole4) | O24: =IF(VOUT_setting=1,1,SQRT(1+(A24*zterm1)^2)) | P24: =IF(VOUT_setting=1,0,ATAN(((A24*zterm1)))) | Q24: =IF(VOUT_setting=1,1,SQRT((1+Afbr-$Q$5*(A24)^2)^2+(A24*$Q$4)^2)) | R24: =IF(VOUT_setting=1,0,ATAN(A24*$Q$4/(1+Afbr-$Q$5*(A24)^2))) | S24: =SQRT((1-(Z24/pterm2))^2+(A24/pterm1)^2) | T24: =IF((ATAN((A24/pterm1)/(1-A24^2/pterm2))>0),ATAN((A24/pterm1)/(1-A24^2/pterm2)),PI()+ATAN((A24/pterm1)/(1-A24^2/pterm2))) | U24: =20*LOG10(((E24*K24*G24*O24)/(C24*I24*S24*M24*Q24))*Adc) | V24: =((F24+L24+H24+P24)-(D24+J24+T24+N24+R24))*radconv | W24: =IF(V24>0,V24,V24+180) | Y24: =IF(U24<0,A24,1000000000) | Z24: =A24^2 | AB24: =20*LOG10((K24/(I24*M24))*AEA) | AC24: =(L24-(J24+N24))*radconv | AE24: =20*LOG10((E24*G24/(C24*S24))*Acs*Am) | AF24: =(F24+H24-(D24+T24))*radconv | AH24: =SUM((U25<0)*(U24>0))*A24 | AI24: =IF(AH24>0,W22,0)
A25: 3.02 | B25: =A25/1000 | C25: =SQRT(1+(A25/pole1)^2) | D25: =ATAN(A25/pole1) | E25: =SQRT(1+(A25/Zero1)^2) | F25: =ATAN(A25/Zero1) | G25: =IF(VIN_nom>Vout, 1, SQRT(1+(A25/z_RHP)^2)) | H25: =IF(VIN_nom>Vout, 0, -ATAN(A25/z_RHP)) | I25: =SQRT(1+(A25/Pole2)^2) | J25: =ATAN(A25/Pole2) | K25: =SQRT(1+(A25/Zero2)^2) | L25: =ATAN(A25/Zero2) | M25: =SQRT(1+(A25/pole4)^2) | N25: =ATAN(A25/pole4) | O25: =IF(VOUT_setting=1,1,SQRT(1+(A25*zterm1)^2)) | P25: =IF(VOUT_setting=1,0,ATAN(((A25*zterm1)))) | Q25: =IF(VOUT_setting=1,1,SQRT((1+Afbr-$Q$5*(A25)^2)^2+(A25*$Q$4)^2)) | R25: =IF(VOUT_setting=1,0,ATAN(A25*$Q$4/(1+Afbr-$Q$5*(A25)^2))) | S25: =SQRT((1-(Z25/pterm2))^2+(A25/pterm1)^2) | T25: =IF((ATAN((A25/pterm1)/(1-A25^2/pterm2))>0),ATAN((A25/pterm1)/(1-A25^2/pterm2)),PI()+ATAN((A25/pterm1)/(1-A25^2/pterm2))) | U25: =20*LOG10(((E25*K25*G25*O25)/(C25*I25*S25*M25*Q25))*Adc) | V25: =((F25+L25+H25+P25)-(D25+J25+T25+N25+R25))*radconv | W25: =IF(V25>0,V25,V25+180) | Y25: =IF(U25<0,A25,1000000000) | Z25: =A25^2 | AB25: =20*LOG10((K25/(I25*M25))*AEA) | AC25: =(L25-(J25+N25))*radconv | AE25: =20*LOG10((E25*G25/(C25*S25))*Acs*Am) | AF25: =(F25+H25-(D25+T25))*radconv | AH25: =SUM((U26<0)*(U25>0))*A25 | AI25: =IF(AH25>0,W23,0)
A26: 3.3113 | B26: =A26/1000 | C26: =SQRT(1+(A26/pole1)^2) | D26: =ATAN(A26/pole1) | E26: =SQRT(1+(A26/Zero1)^2) | F26: =ATAN(A26/Zero1) | G26: =IF(VIN_nom>Vout, 1, SQRT(1+(A26/z_RHP)^2)) | H26: =IF(VIN_nom>Vout, 0, -ATAN(A26/z_RHP)) | I26: =SQRT(1+(A26/Pole2)^2) | J26: =ATAN(A26/Pole2) | K26: =SQRT(1+(A26/Zero2)^2) | L26: =ATAN(A26/Zero2) | M26: =SQRT(1+(A26/pole4)^2) | N26: =ATAN(A26/pole4) | O26: =IF(VOUT_setting=1,1,SQRT(1+(A26*zterm1)^2)) | P26: =IF(VOUT_setting=1,0,ATAN(((A26*zterm1)))) | Q26: =IF(VOUT_setting=1,1,SQRT((1+Afbr-$Q$5*(A26)^2)^2+(A26*$Q$4)^2)) | R26: =IF(VOUT_setting=1,0,ATAN(A26*$Q$4/(1+Afbr-$Q$5*(A26)^2))) | S26: =SQRT((1-(Z26/pterm2))^2+(A26/pterm1)^2) | T26: =IF((ATAN((A26/pterm1)/(1-A26^2/pterm2))>0),ATAN((A26/pterm1)/(1-A26^2/pterm2)),PI()+ATAN((A26/pterm1)/(1-A26^2/pterm2))) | U26: =20*LOG10(((E26*K26*G26*O26)/(C26*I26*S26*M26*Q26))*Adc) | V26: =((F26+L26+H26+P26)-(D26+J26+T26+N26+R26))*radconv | W26: =IF(V26>0,V26,V26+180) | Y26: =IF(U26<0,A26,1000000000) | Z26: =A26^2 | AB26: =20*LOG10((K26/(I26*M26))*AEA) | AC26: =(L26-(J26+N26))*radconv | AE26: =20*LOG10((E26*G26/(C26*S26))*Acs*Am) | AF26: =(F26+H26-(D26+T26))*radconv | AH26: =SUM((U27<0)*(U26>0))*A26 | AI26: =IF(AH26>0,W24,0)
... A89: 1096.5 | B89: =A89/1000 | C89: =SQRT(1+(A89/pole1)^2) | D89: =ATAN(A89/pole1) | E89: =SQRT(1+(A89/Zero1)^2) | F89: =ATAN(A89/Zero1) | G89: =IF(VIN_nom>Vout, 1, SQRT(1+(A89/z_RHP)^2)) | H89: =IF(VIN_nom>Vout, 0, -ATAN(A89/z_RHP)) | I89: =SQRT(1+(A89/Pole2)^2) | J89: =ATAN(A89/Pole2) | K89: =SQRT(1+(A89/Zero2)^2) | L89: =ATAN(A89/Zero2) | M89: =SQRT(1+(A89/pole4)^2) | N89: =ATAN(A89/pole4) | O89: =IF(VOUT_setting=1,1,SQRT(1+(A89*zterm1)^2)) | P89: =IF(VOUT_setting=1,0,ATAN(((A89*zterm1)))) | Q89: =IF(VOUT_setting=1,1,SQRT((1+Afbr-$Q$5*(A89)^2)^2+(A89*$Q$4)^2)) | R89: =IF(VOUT_setting=1,0,ATAN(A89*$Q$4/(1+Afbr-$Q$5*(A89)^2))) | S89: =SQRT((1-(Z89/pterm2))^2+(A89/pterm1)^2) | T89: =IF((ATAN((A89/pterm1)/(1-A89^2/pterm2))>0),ATAN((A89/pterm1)/(1-A89^2/pterm2)),PI()+ATAN((A89/pterm1)/(1-A89^2/pterm2))) | U89: =20*LOG10(((E89*K89*G89*O89)/(C89*I89*S89*M89*Q89))*Adc) | V89: =((F89+L89+H89+P89)-(D89+J89+T89+N89+R89))*radconv | W89: =IF(V89>0,V89,V89+180) | Y89: =IF(U89<0,A89,1000000000) | Z89: =A89^2 | AB89: =20*LOG10((K89/(I89*M89))*AEA) | AC89: =(L89-(J89+N89))*radconv | AE89: =20*LOG10((E89*G89/(C89*S89))*Acs*Am) | AF89: =(F89+H89-(D89+T89))*radconv | AH89: =SUM((U90<0)*(U89>0))*A89 | AI89: =IF(AH89>0,W87,0)
A90: 1202.3 | B90: =A90/1000 | C90: =SQRT(1+(A90/pole1)^2) | D90: =ATAN(A90/pole1) | E90: =SQRT(1+(A90/Zero1)^2) | F90: =ATAN(A90/Zero1) | G90: =IF(VIN_nom>Vout, 1, SQRT(1+(A90/z_RHP)^2)) | H90: =IF(VIN_nom>Vout, 0, -ATAN(A90/z_RHP)) | I90: =SQRT(1+(A90/Pole2)^2) | J90: =ATAN(A90/Pole2) | K90: =SQRT(1+(A90/Zero2)^2) | L90: =ATAN(A90/Zero2) | M90: =SQRT(1+(A90/pole4)^2) | N90: =ATAN(A90/pole4) | O90: =IF(VOUT_setting=1,1,SQRT(1+(A90*zterm1)^2)) | P90: =IF(VOUT_setting=1,0,ATAN(((A90*zterm1)))) | Q90: =IF(VOUT_setting=1,1,SQRT((1+Afbr-$Q$5*(A90)^2)^2+(A90*$Q$4)^2)) | R90: =IF(VOUT_setting=1,0,ATAN(A90*$Q$4/(1+Afbr-$Q$5*(A90)^2))) | S90: =SQRT((1-(Z90/pterm2))^2+(A90/pterm1)^2) | T90: =IF((ATAN((A90/pterm1)/(1-A90^2/pterm2))>0),ATAN((A90/pterm1)/(1-A90^2/pterm2)),PI()+ATAN((A90/pterm1)/(1-A90^2/pterm2))) | U90: =20*LOG10(((E90*K90*G90*O90)/(C90*I90*S90*M90*Q90))*Adc) | V90: =((F90+L90+H90+P90)-(D90+J90+T90+N90+R90))*radconv | W90: =IF(V90>0,V90,V90+180) | Y90: =IF(U90<0,A90,1000000000) | Z90: =A90^2 | AB90: =20*LOG10((K90/(I90*M90))*AEA) | AC90: =(L90-(J90+N90))*radconv | AE90: =20*LOG10((E90*G90/(C90*S90))*Acs*Am) | AF90: =(F90+H90-(D90+T90))*radconv | AH90: =SUM((U91<0)*(U90>0))*A90 | AI90: =IF(AH90>0,W90,0)
A91: 1318.3 | B91: =A91/1000 | C91: =SQRT(1+(A91/pole1)^2) | D91: =ATAN(A91/pole1) | E91: =SQRT(1+(A91/Zero1)^2) | F91: =ATAN(A91/Zero1) | G91: =IF(VIN_nom>Vout, 1, SQRT(1+(A91/z_RHP)^2)) | H91: =IF(VIN_nom>Vout, 0, -ATAN(A91/z_RHP)) | I91: =SQRT(1+(A91/Pole2)^2) | J91: =ATAN(A91/Pole2) | K91: =SQRT(1+(A91/Zero2)^2) | L91: =ATAN(A91/Zero2) | M91: =SQRT(1+(A91/pole4)^2) | N91: =ATAN(A91/pole4) | O91: =IF(VOUT_setting=1,1,SQRT(1+(A91*zterm1)^2)) | P91: =IF(VOUT_setting=1,0,ATAN(((A91*zterm1)))) | Q91: =IF(VOUT_setting=1,1,SQRT((1+Afbr-$Q$5*(A91)^2)^2+(A91*$Q$4)^2)) | R91: =IF(VOUT_setting=1,0,ATAN(A91*$Q$4/(1+Afbr-$Q$5*(A91)^2))) | S91: =SQRT((1-(Z91/pterm2))^2+(A91/pterm1)^2) | T91: =IF((ATAN((A91/pterm1)/(1-A91^2/pterm2))>0),ATAN((A91/pterm1)/(1-A91^2/pterm2)),PI()+ATAN((A91/pterm1)/(1-A91^2/pterm2))) | U91: =20*LOG10(((E91*K91*G91*O91)/(C91*I91*S91*M91*Q91))*Adc) | V91: =((F91+L91+H91+P91)-(D91+J91+T91+N91+R91))*radconv | W91: =IF(V91>0,V91,V91+180) | Y91: =IF(U91<0,A91,1000000000) | Z91: =A91^2 | AB91: =20*LOG10((K91/(I91*M91))*AEA) | AC91: =(L91-(J91+N91))*radconv | AE91: =20*LOG10((E91*G91/(C91*S91))*Acs*Am) | AF91: =(F91+H91-(D91+T91))*radconv | AH91: =SUM((U92<0)*(U91>0))*A91 | AI91: =IF(AH91>0,W91,0)
A92: 1445.4 | B92: =A92/1000 | C92: =SQRT(1+(A92/pole1)^2) | D92: =ATAN(A92/pole1) | E92: =SQRT(1+(A92/Zero1)^2) | F92: =ATAN(A92/Zero1) | G92: =IF(VIN_nom>Vout, 1, SQRT(1+(A92/z_RHP)^2)) | H92: =IF(VIN_nom>Vout, 0, -ATAN(A92/z_RHP)) | I92: =SQRT(1+(A92/Pole2)^2) | J92: =ATAN(A92/Pole2) | K92: =SQRT(1+(A92/Zero2)^2) | L92: =ATAN(A92/Zero2) | M92: =SQRT(1+(A92/pole4)^2) | N92: =ATAN(A92/pole4) | O92: =IF(VOUT_setting=1,1,SQRT(1+(A92*zterm1)^2)) | P92: =IF(VOUT_setting=1,0,ATAN(((A92*zterm1)))) | Q92: =IF(VOUT_setting=1,1,SQRT((1+Afbr-$Q$5*(A92)^2)^2+(A92*$Q$4)^2)) | R92: =IF(VOUT_setting=1,0,ATAN(A92*$Q$4/(1+Afbr-$Q$5*(A92)^2))) | S92: =SQRT((1-(Z92/pterm2))^2+(A92/pterm1)^2) | T92: =IF((ATAN((A92/pterm1)/(1-A92^2/pterm2))>0),ATAN((A92/pterm1)/(1-A92^2/pterm2)),PI()+ATAN((A92/pterm1)/(1-A92^2/pterm2))) | U92: =20*LOG10(((E92*K92*G92*O92)/(C92*I92*S92*M92*Q92))*Adc) | V92: =((F92+L92+H92+P92)-(D92+J92+T92+N92+R92))*radconv | W92: =IF(V92>0,V92,V92+180) | Y92: =IF(U92<0,A92,1000000000) | Z92: =A92^2 | AB92: =20*LOG10((K92/(I92*M92))*AEA) | AC92: =(L92-(J92+N92))*radconv | AE92: =20*LOG10((E92*G92/(C92*S92))*Acs*Am) | AF92: =(F92+H92-(D92+T92))*radconv | AH92: =SUM((U93<0)*(U92>0))*A92 | AI92: =IF(AH92>0,W92,0)
A93: 1584.9 | B93: =A93/1000 | C93: =SQRT(1+(A93/pole1)^2) | D93: =ATAN(A93/pole1) | E93: =SQRT(1+(A93/Zero1)^2) | F93: =ATAN(A93/Zero1) | G93: =IF(VIN_nom>Vout, 1, SQRT(1+(A93/z_RHP)^2)) | H93: =IF(VIN_nom>Vout, 0, -ATAN(A93/z_RHP)) | I93: =SQRT(1+(A93/Pole2)^2) | J93: =ATAN(A93/Pole2) | K93: =SQRT(1+(A93/Zero2)^2) | L93: =ATAN(A93/Zero2) | M93: =SQRT(1+(A93/pole4)^2) | N93: =ATAN(A93/pole4) | O93: =IF(VOUT_setting=1,1,SQRT(1+(A93*zterm1)^2)) | P93: =IF(VOUT_setting=1,0,ATAN(((A93*zterm1)))) | Q93: =IF(VOUT_setting=1,1,SQRT((1+Afbr-$Q$5*(A93)^2)^2+(A93*$Q$4)^2)) | R93: =IF(VOUT_setting=1,0,ATAN(A93*$Q$4/(1+Afbr-$Q$5*(A93)^2))) | S93: =SQRT((1-(Z93/pterm2))^2+(A93/pterm1)^2) | T93: =IF((ATAN((A93/pterm1)/(1-A93^2/pterm2))>0),ATAN((A93/pterm1)/(1-A93^2/pterm2)),PI()+ATAN((A93/pterm1)/(1-A93^2/pterm2))) | U93: =20*LOG10(((E93*K93*G93*O93)/(C93*I93*S93*M93*Q93))*Adc) | V93: =((F93+L93+H93+P93)-(D93+J93+T93+N93+R93))*radconv | W93: =IF(V93>0,V93,V93+180) | Y93: =IF(U93<0,A93,1000000000) | Z93: =A93^2 | AB93: =20*LOG10((K93/(I93*M93))*AEA) | AC93: =(L93-(J93+N93))*radconv | AE93: =20*LOG10((E93*G93/(C93*S93))*Acs*Am) | AF93: =(F93+H93-(D93+T93))*radconv | AH93: =SUM((U94<0)*(U93>0))*A93 | AI93: =IF(AH93>0,W93,0)
A94: 1737.8 | B94: =A94/1000 | C94: =SQRT(1+(A94/pole1)^2) | D94: =ATAN(A94/pole1) | E94: =SQRT(1+(A94/Zero1)^2) | F94: =ATAN(A94/Zero1) | G94: =IF(VIN_nom>Vout, 1, SQRT(1+(A94/z_RHP)^2)) | H94: =IF(VIN_nom>Vout, 0, -ATAN(A94/z_RHP)) | I94: =SQRT(1+(A94/Pole2)^2) | J94: =ATAN(A94/Pole2) | K94: =SQRT(1+(A94/Zero2)^2) | L94: =ATAN(A94/Zero2) | M94: =SQRT(1+(A94/pole4)^2) | N94: =ATAN(A94/pole4) | O94: =IF(VOUT_setting=1,1,SQRT(1+(A94*zterm1)^2)) | P94: =IF(VOUT_setting=1,0,ATAN(((A94*zterm1)))) | Q94: =IF(VOUT_setting=1,1,SQRT((1+Afbr-$Q$5*(A94)^2)^2+(A94*$Q$4)^2)) | R94: =IF(VOUT_setting=1,0,ATAN(A94*$Q$4/(1+Afbr-$Q$5*(A94)^2))) | S94: =SQRT((1-(Z94/pterm2))^2+(A94/pterm1)^2) | T94: =IF((ATAN((A94/pterm1)/(1-A94^2/pterm2))>0),ATAN((A94/pterm1)/(1-A94^2/pterm2)),PI()+ATAN((A94/pterm1)/(1-A94^2/pterm2))) | U94: =20*LOG10(((E94*K94*G94*O94)/(C94*I94*S94*M94*Q94))*Adc) | V94: =((F94+L94+H94+P94)-(D94+J94+T94+N94+R94))*radconv | W94: =IF(V94>0,V94,V94+180) | Y94: =IF(U94<0,A94,1000000000) | Z94: =A94^2 | AB94: =20*LOG10((K94/(I94*M94))*AEA) | AC94: =(L94-(J94+N94))*radconv | AE94: =20*LOG10((E94*G94/(C94*S94))*Acs*Am) | AF94: =(F94+H94-(D94+T94))*radconv | AH94: =SUM((U95<0)*(U94>0))*A94 | AI94: =IF(AH94>0,W94,0)
A95: 1905.5 | B95: =A95/1000 | C95: =SQRT(1+(A95/pole1)^2) | D95: =ATAN(A95/pole1) | E95: =SQRT(1+(A95/Zero1)^2) | F95: =ATAN(A95/Zero1) | G95: =IF(VIN_nom>Vout, 1, SQRT(1+(A95/z_RHP)^2)) | H95: =IF(VIN_nom>Vout, 0, -ATAN(A95/z_RHP)) | I95: =SQRT(1+(A95/Pole2)^2) | J95: =ATAN(A95/Pole2) | K95: =SQRT(1+(A95/Zero2)^2) | L95: =ATAN(A95/Zero2) | M95: =SQRT(1+(A95/pole4)^2) | N95: =ATAN(A95/pole4) | O95: =IF(VOUT_setting=1,1,SQRT(1+(A95*zterm1)^2)) | P95: =IF(VOUT_setting=1,0,ATAN(((A95*zterm1)))) | Q95: =IF(VOUT_setting=1,1,SQRT((1+Afbr-$Q$5*(A95)^2)^2+(A95*$Q$4)^2)) | R95: =IF(VOUT_setting=1,0,ATAN(A95*$Q$4/(1+Afbr-$Q$5*(A95)^2))) | S95: =SQRT((1-(Z95/pterm2))^2+(A95/pterm1)^2) | T95: =IF((ATAN((A95/pterm1)/(1-A95^2/pterm2))>0),ATAN((A95/pterm1)/(1-A95^2/pterm2)),PI()+ATAN((A95/pterm1)/(1-A95^2/pterm2))) | U95: =20*LOG10(((E95*K95*G95*O95)/(C95*I95*S95*M95*Q95))*Adc) | V95: =((F95+L95+H95+P95)-(D95+J95+T95+N95+R95))*radconv | W95: =IF(V95>0,V95,V95+180) | Y95: =IF(U95<0,A95,1000000000) | Z95: =A95^2 | AB95: =20*LOG10((K95/(I95*M95))*AEA) | AC95: =(L95-(J95+N95))*radconv | AE95: =20*LOG10((E95*G95/(C95*S95))*Acs*Am) | AF95: =(F95+H95-(D95+T95))*radconv | AH95: =SUM((U96<0)*(U95>0))*A95 | AI95: =IF(AH95>0,W95,0)
A96: 2089.3 | B96: =A96/1000 | C96: =SQRT(1+(A96/pole1)^2) | D96: =ATAN(A96/pole1) | E96: =SQRT(1+(A96/Zero1)^2) | F96: =ATAN(A96/Zero1) | G96: =IF(VIN_nom>Vout, 1, SQRT(1+(A96/z_RHP)^2)) | H96: =IF(VIN_nom>Vout, 0, -ATAN(A96/z_RHP)) | I96: =SQRT(1+(A96/Pole2)^2) | J96: =ATAN(A96/Pole2) | K96: =SQRT(1+(A96/Zero2)^2) | L96: =ATAN(A96/Zero2) | M96: =SQRT(1+(A96/pole4)^2) | N96: =ATAN(A96/pole4) | O96: =IF(VOUT_setting=1,1,SQRT(1+(A96*zterm1)^2)) | P96: =IF(VOUT_setting=1,0,ATAN(((A96*zterm1)))) | Q96: =IF(VOUT_setting=1,1,SQRT((1+Afbr-$Q$5*(A96)^2)^2+(A96*$Q$4)^2)) | R96: =IF(VOUT_setting=1,0,ATAN(A96*$Q$4/(1+Afbr-$Q$5*(A96)^2))) | S96: =SQRT((1-(Z96/pterm2))^2+(A96/pterm1)^2) | T96: =IF((ATAN((A96/pterm1)/(1-A96^2/pterm2))>0),ATAN((A96/pterm1)/(1-A96^2/pterm2)),PI()+ATAN((A96/pterm1)/(1-A96^2/pterm2))) | U96: =20*LOG10(((E96*K96*G96*O96)/(C96*I96*S96*M96*Q96))*Adc) | V96: =((F96+L96+H96+P96)-(D96+J96+T96+N96+R96))*radconv | W96: =IF(V96>0,V96,V96+180) | Y96: =IF(U96<0,A96,1000000000) | Z96: =A96^2 | AB96: =20*LOG10((K96/(I96*M96))*AEA) | AC96: =(L96-(J96+N96))*radconv | AE96: =20*LOG10((E96*G96/(C96*S96))*Acs*Am) | AF96: =(F96+H96-(D96+T96))*radconv | AH96: =SUM((U97<0)*(U96>0))*A96 | AI96: =IF(AH96>0,W96,0)
A97: 2290.9 | B97: =A97/1000 | C97: =SQRT(1+(A97/pole1)^2) | D97: =ATAN(A97/pole1) | E97: =SQRT(1+(A97/Zero1)^2) | F97: =ATAN(A97/Zero1) | G97: =IF(VIN_nom>Vout, 1, SQRT(1+(A97/z_RHP)^2)) | H97: =IF(VIN_nom>Vout, 0, -ATAN(A97/z_RHP)) | I97: =SQRT(1+(A97/Pole2)^2) | J97: =ATAN(A97/Pole2) | K97: =SQRT(1+(A97/Zero2)^2) | L97: =ATAN(A97/Zero2) | M97: =SQRT(1+(A97/pole4)^2) | N97: =ATAN(A97/pole4) | O97: =IF(VOUT_setting=1,1,SQRT(1+(A97*zterm1)^2)) | P97: =IF(VOUT_setting=1,0,ATAN(((A97*zterm1)))) | Q97: =IF(VOUT_setting=1,1,SQRT((1+Afbr-$Q$5*(A97)^2)^2+(A97*$Q$4)^2)) | R97: =IF(VOUT_setting=1,0,ATAN(A97*$Q$4/(1+Afbr-$Q$5*(A97)^2))) | S97: =SQRT((1-(Z97/pterm2))^2+(A97/pterm1)^2) | T97: =IF((ATAN((A97/pterm1)/(1-A97^2/pterm2))>0),ATAN((A97/pterm1)/(1-A97^2/pterm2)),PI()+ATAN((A97/pterm1)/(1-A97^2/pterm2))) | U97: =20*LOG10(((E97*K97*G97*O97)/(C97*I97*S97*M97*Q97))*Adc) | V97: =((F97+L97+H97+P97)-(D97+J97+T97+N97+R97))*radconv | W97: =IF(V97>0,V97,V97+180) | Y97: =IF(U97<0,A97,1000000000) | Z97: =A97^2 | AB97: =20*LOG10((K97/(I97*M97))*AEA) | AC97: =(L97-(J97+N97))*radconv | AE97: =20*LOG10((E97*G97/(C97*S97))*Acs*Am) | AF97: =(F97+H97-(D97+T97))*radconv | AH97: =SUM((U98<0)*(U97>0))*A97 | AI97: =IF(AH97>0,W97,0)
A98: 2511.9 | B98: =A98/1000 | C98: =SQRT(1+(A98/pole1)^2) | D98: =ATAN(A98/pole1) | E98: =SQRT(1+(A98/Zero1)^2) | F98: =ATAN(A98/Zero1) | G98: =IF(VIN_nom>Vout, 1, SQRT(1+(A98/z_RHP)^2)) | H98: =IF(VIN_nom>Vout, 0, -ATAN(A98/z_RHP)) | I98: =SQRT(1+(A98/Pole2)^2) | J98: =ATAN(A98/Pole2) | K98: =SQRT(1+(A98/Zero2)^2) | L98: =ATAN(A98/Zero2) | M98: =SQRT(1+(A98/pole4)^2) | N98: =ATAN(A98/pole4) | O98: =IF(VOUT_setting=1,1,SQRT(1+(A98*zterm1)^2)) | P98: =IF(VOUT_setting=1,0,ATAN(((A98*zterm1)))) | Q98: =IF(VOUT_setting=1,1,SQRT((1+Afbr-$Q$5*(A98)^2)^2+(A98*$Q$4)^2)) | R98: =IF(VOUT_setting=1,0,ATAN(A98*$Q$4/(1+Afbr-$Q$5*(A98)^2))) | S98: =SQRT((1-(Z98/pterm2))^2+(A98/pterm1)^2) | T98: =IF((ATAN((A98/pterm1)/(1-A98^2/pterm2))>0),ATAN((A98/pterm1)/(1-A98^2/pterm2)),PI()+ATAN((A98/pterm1)/(1-A98^2/pterm2))) | U98: =20*LOG10(((E98*K98*G98*O98)/(C98*I98*S98*M98*Q98))*Adc) | V98: =((F98+L98+H98+P98)-(D98+J98+T98+N98+R98))*radconv | W98: =IF(V98>0,V98,V98+180) | Y98: =IF(U98<0,A98,1000000000) | Z98: =A98^2 | AB98: =20*LOG10((K98/(I98*M98))*AEA) | AC98: =(L98-(J98+N98))*radconv | AE98: =20*LOG10((E98*G98/(C98*S98))*Acs*Am) | AF98: =(F98+H98-(D98+T98))*radconv | AH98: =SUM((U99<0)*(U98>0))*A98 | AI98: =IF(AH98>0,W98,0)
A99: 2754.2 | B99: =A99/1000 | C99: =SQRT(1+(A99/pole1)^2) | D99: =ATAN(A99/pole1) | E99: =SQRT(1+(A99/Zero1)^2) | F99: =ATAN(A99/Zero1) | G99: =IF(VIN_nom>Vout, 1, SQRT(1+(A99/z_RHP)^2)) | H99: =IF(VIN_nom>Vout, 0, -ATAN(A99/z_RHP)) | I99: =SQRT(1+(A99/Pole2)^2) | J99: =ATAN(A99/Pole2) | K99: =SQRT(1+(A99/Zero2)^2) | L99: =ATAN(A99/Zero2) | M99: =SQRT(1+(A99/pole4)^2) | N99: =ATAN(A99/pole4) | O99: =IF(VOUT_setting=1,1,SQRT(1+(A99*zterm1)^2)) | P99: =IF(VOUT_setting=1,0,ATAN(((A99*zterm1)))) | Q99: =IF(VOUT_setting=1,1,SQRT((1+Afbr-$Q$5*(A99)^2)^2+(A99*$Q$4)^2)) | R99: =IF(VOUT_setting=1,0,ATAN(A99*$Q$4/(1+Afbr-$Q$5*(A99)^2))) | S99: =SQRT((1-(Z99/pterm2))^2+(A99/pterm1)^2) | T99: =IF((ATAN((A99/pterm1)/(1-A99^2/pterm2))>0),ATAN((A99/pterm1)/(1-A99^2/pterm2)),PI()+ATAN((A99/pterm1)/(1-A99^2/pterm2))) | U99: =20*LOG10(((E99*K99*G99*O99)/(C99*I99*S99*M99*Q99))*Adc) | V99: =((F99+L99+H99+P99)-(D99+J99+T99+N99+R99))*radconv | W99: =IF(V99>0,V99,V99+180) | Y99: =IF(U99<0,A99,1000000000) | Z99: =A99^2 | AB99: =20*LOG10((K99/(I99*M99))*AEA) | AC99: =(L99-(J99+N99))*radconv | AE99: =20*LOG10((E99*G99/(C99*S99))*Acs*Am) | AF99: =(F99+H99-(D99+T99))*radconv | AH99: =SUM((U100<0)*(U99>0))*A99 | AI99: =IF(AH99>0,W99,0)
A100: 3020 | B100: =A100/1000 | C100: =SQRT(1+(A100/pole1)^2) | D100: =ATAN(A100/pole1) | E100: =SQRT(1+(A100/Zero1)^2) | F100: =ATAN(A100/Zero1) | G100: =IF(VIN_nom>Vout, 1, SQRT(1+(A100/z_RHP)^2)) | H100: =IF(VIN_nom>Vout, 0, -ATAN(A100/z_RHP)) | I100: =SQRT(1+(A100/Pole2)^2) | J100: =ATAN(A100/Pole2) | K100: =SQRT(1+(A100/Zero2)^2) | L100: =ATAN(A100/Zero2) | M100: =SQRT(1+(A100/pole4)^2) | N100: =ATAN(A100/pole4) | O100: =IF(VOUT_setting=1,1,SQRT(1+(A100*zterm1)^2)) | P100: =IF(VOUT_setting=1,0,ATAN(((A100*zterm1)))) | Q100: =IF(VOUT_setting=1,1,SQRT((1+Afbr-$Q$5*(A100)^2)^2+(A100*$Q$4)^2)) | R100: =IF(VOUT_setting=1,0,ATAN(A100*$Q$4/(1+Afbr-$Q$5*(A100)^2))) | S100: =SQRT((1-(Z100/pterm2))^2+(A100/pterm1)^2) | T100: =IF((ATAN((A100/pterm1)/(1-A100^2/pterm2))>0),ATAN((A100/pterm1)/(1-A100^2/pterm2)),PI()+ATAN((A100/pterm1)/(1-A100^2/pterm2))) | U100: =20*LOG10(((E100*K100*G100*O100)/(C100*I100*S100*M100*Q100))*Adc) | V100: =((F100+L100+H100+P100)-(D100+J100+T100+N100+R100))*radconv | W100: =IF(V100>0,V100,V100+180) | Y100: =IF(U100<0,A100,1000000000) | Z100: =A100^2 | AB100: =20*LOG10((K100/(I100*M100))*AEA) | AC100: =(L100-(J100+N100))*radconv | AE100: =20*LOG10((E100*G100/(C100*S100))*Acs*Am) | AF100: =(F100+H100-(D100+T100))*radconv | AH100: =SUM((U101<0)*(U100>0))*A100 | AI100: =IF(AH100>0,W100,0)
A101: 3311.3 | B101: =A101/1000 | C101: =SQRT(1+(A101/pole1)^2) | D101: =ATAN(A101/pole1) | E101: =SQRT(1+(A101/Zero1)^2) | F101: =ATAN(A101/Zero1) | G101: =IF(VIN_nom>Vout, 1, SQRT(1+(A101/z_RHP)^2)) | H101: =IF(VIN_nom>Vout, 0, -ATAN(A101/z_RHP)) | I101: =SQRT(1+(A101/Pole2)^2) | J101: =ATAN(A101/Pole2) | K101: =SQRT(1+(A101/Zero2)^2) | L101: =ATAN(A101/Zero2) | M101: =SQRT(1+(A101/pole4)^2) | N101: =ATAN(A101/pole4) | O101: =IF(VOUT_setting=1,1,SQRT(1+(A101*zterm1)^2)) | P101: =IF(VOUT_setting=1,0,ATAN(((A101*zterm1)))) | Q101: =IF(VOUT_setting=1,1,SQRT((1+Afbr-$Q$5*(A101)^2)^2+(A101*$Q$4)^2)) | R101: =IF(VOUT_setting=1,0,ATAN(A101*$Q$4/(1+Afbr-$Q$5*(A101)^2))) | S101: =SQRT((1-(Z101/pterm2))^2+(A101/pterm1)^2) | T101: =IF((ATAN((A101/pterm1)/(1-A101^2/pterm2))>0),ATAN((A101/pterm1)/(1-A101^2/pterm2)),PI()+ATAN((A101/pterm1)/(1-A101^2/pterm2))) | U101: =20*LOG10(((E101*K101*G101*O101)/(C101*I101*S101*M101*Q101))*Adc) | V101: =((F101+L101+H101+P101)-(D101+J101+T101+N101+R101))*radconv | W101: =IF(V101>0,V101,V101+180) | Y101: =IF(U101<0,A101,1000000000) | Z101: =A101^2 | AB101: =20*LOG10((K101/(I101*M101))*AEA) | AC101: =(L101-(J101+N101))*radconv | AE101: =20*LOG10((E101*G101/(C101*S101))*Acs*Am) | AF101: =(F101+H101-(D101+T101))*radconv | AH101: =SUM((U102<0)*(U101>0))*A101 | AI101: =IF(AH101>0,W101,0)
... A613: 1000000 | B613: =A613/1000 | C613: =SQRT(1+(A613/pole1)^2) | D613: =ATAN(A613/pole1) | E613: =SQRT(1+(A613/Zero1)^2) | F613: =ATAN(A613/Zero1) | G613: =IF(VIN_nom>Vout, 1, SQRT(1+(A613/z_RHP)^2)) | H613: =IF(VIN_nom>Vout, 0, -ATAN(A613/z_RHP)) | I613: =SQRT(1+(A613/Pole2)^2) | J613: =ATAN(A613/Pole2) | K613: =SQRT(1+(A613/Zero2)^2) | L613: =ATAN(A613/Zero2) | M613: =SQRT(1+(A613/pole4)^2) | N613: =ATAN(A613/pole4) | O613: =IF(VOUT_setting=1,1,SQRT(1+(A613*zterm1)^2)) | P613: =IF(VOUT_setting=1,0,ATAN(((A613*zterm1)))) | Q613: =IF(VOUT_setting=1,1,SQRT((1+Afbr-$Q$5*(A613)^2)^2+(A613*$Q$4)^2)) | R613: =IF(VOUT_setting=1,0,ATAN(A613*$Q$4/(1+Afbr-$Q$5*(A613)^2))) | S613: =SQRT((1-(Z613/pterm2))^2+(A613/pterm1)^2) | T613: =IF((ATAN((A613/pterm1)/(1-A613^2/pterm2))>0),ATAN((A613/pterm1)/(1-A613^2/pterm2)),PI()+ATAN((A613/pterm1)/(1-A613^2/pterm2))) | U613: =20*LOG10(((E613*K613*G613*O613)/(C613*I613*S613*M613*Q613))*Adc) | V613: =((F613+L613+H613+P613)-(D613+J613+T613+N613+R613))*radconv | W613: =IF(V613>0,V613,V613+180) | Y613: =IF(U613<0,A613,1000000000) | Z613: =A613^2 | AB613: =20*LOG10((K613/(I613*M613))*AEA) | AC613: =(L613-(J613+N613))*radconv | AE613: =20*LOG10((E613*G613/(C613*S613))*Acs*Am) | AF613: =(F613+H613-(D613+T613))*radconv | AH613: =SUM((U614<0)*(U613>0))*A613 | AI613: =IF(AH613>0,W613,0)
A616: Pole/Zero Locations for Chart
A617: =U4*1000 | C617: =SQRT(1+(A617/pole1)^2) | D617: =ATAN(A617/pole1) | E617: =SQRT(1+(A617/Zero1)^2) | F617: =ATAN(A617/Zero1) | G617: =IF(VIN_nom>Vout, 1, SQRT(1+(A617/z_RHP)^2)) | H617: =IF(VIN_nom>Vout, 0, -ATAN(A617/z_RHP)) | I617: =SQRT(1+(A617/Pole2)^2) | J617: =ATAN(A617/Pole2) | K617: =SQRT(1+(A617/Zero2)^2) | L617: =ATAN(A617/Zero2) | M617: =SQRT(1+(A617/pole4)^2) | N617: =ATAN(A617/pole4) | O617: =IF(VOUT_setting=1,1,SQRT(1+(A617*zterm1)^2)) | P617: =IF(VOUT_setting=1,0,ATAN(((A617*zterm1)))) | Q617: =IF(VOUT_setting=1,1,SQRT((1+Afbr-$Q$5*(A617)^2)^2+(A617*$Q$4)^2)) | R617: =IF(VOUT_setting=1,0,ATAN(A617*$Q$4/(1+Afbr-$Q$5*(A617)^2))) | S617: =SQRT((1-(A617^2/(pole3^2)))^2+(A617/(Q*pole3))^2) | T617: =ATAN((A617/(Q*pole3))/(1-A617^2/pole3^2)) | U617: =20*LOG10(((E617*K617*G617*O617)/(C617*I617*S617*M617*Q617))*Adc) | V617: =((F617+L617+H617+P617)-(D617+J617+T617+N617+R617))*radconv | W617: =IF(V617>0,V617,V617+180) | X617: crossover | AB617: =20*LOG10((K617/(I617*M617))*AEA) | AC617: =(L617-(J617+N617))*radconv | AE617: =20*LOG10((E617*G617/(C617*S617))*Acs*Am) | AF617: =(F617+H617-(D617+T617))*radconv
...

Sheet Bode Plot Management
J1: Single or dual output (MODE) | N1: 3.3V or 5V fixed (FB1/2)
A2: =CHOOSE(BODE_PLOT_TYPE, "BODE_PLOT_Ch1", "BODE_PLOT_Ch2") | J2: With/without dither (DITH) | N2: With/without VOUT connected to VCCX
J3: FPWM or DEM (DEMB)
J4: Shunt or inductor DCR current sensing
F6: =INDIRECT(A2)

Sheet Efficiency Calculations
A1: BUCK CONTROLLER POWER DESIGN TOOL
H2: =AV19 | I2: 10% load
H3: =AV59 | I3: 50% load | AP3: =IF(MODE=1, (Qg_Q1+Qg_Q2)*Fsw*Vin, (Qg_Q1+Qg_Q2+Qg_Q3+Qg_Q4)*Fsw*Vin)
H4: =AV109 | I4: 100% load | AO4: I_VCC | AP4: =(Qg_Q1+Qg_Q2)*Fsw*1000 | AQ4: mA | AR4: =AP4*5/1000
A6: Enter the values of your design and MOSFET datasheet specifications below. Note that thermal resistance (θJA) will change when components are placed on the PCB
G7: Operating Point Condtions | R7: Filter Inductor | V7: Cout | Y7: Cin | AB7: High-side BUCK "Control" MOSFET Losses | AH7: Low-side BUCK "Sync" MOSFET Losses | AL7: External Diode | AM7: Diode/FET | AN7: Sense Rs | AO7: Controller IC Losses | AT7: RESULTS | AZ7: Consolidated Buck/Boost Efficiency & Losses
A8: Input Parameters | G8: Step | H8: Vin | I8: Mode | J8: Iout | K8: Iout/ phase | L8: Iin | M8: Duty Cycle BUCK Leg | N8: Ripple Current pk-pk | O8: Peak Inductor Current | P8: Valley Inductor Current | Q8: SW node voltage at Q1 turn-on | R8: Irms Lf | S8: DCR Loss | T8: Core Loss | U8: Total Inductor Loss | V8: Irms Cout | W8: Cout ESR Loss | X8: Total Cout Loss | Y8: Irms Cin | Z8: Cin ESR Loss | AA8: Total Cin Loss | AB8: Irms | AC8: RDS(on) Loss | AD8: Transition Loss (not including capacitive loss) | AE8: MOSFET Output Capacitance Loss | AF8: Dead Time Loss | AG8: Total Control MOSFET Loss | AH8: Irms | AI8: RDS(on) Loss | AJ8: Deadtime Loss | AK8: Total Sync MOSFET Loss | AL8: Deadtime Loss | AM8: Reverse Recovery Loss | AN8: Isense Shunt Loss | AO8: IQ Loss | AP8: Switching Current Loss | AQ8: Switching Current Diss | AR8: LDO Loss Saved from Gate Drive Current (ext VCC) | AS8: Total IC Loss | AT8: Total Loss | AU8: Pout | AV8: EFF, h | AW8: =IF(Vin>Vout, "Buck ''CONTROL'' MOSFET Temp Rise", "Boost ''CONTROL'' MOSFET Temp Rise") | AX8: =IF(Vin>Vout, "Buck ''SYNC'' MOSFET Temp Rise", "Boost ''SYNC'' MOSFET Temp Rise") | AZ8: h | BA8: Inductor Cu & Core Loss | BB8: Total MOSFET Loss | BC8: Control MOSFET Loss | BD8: SYNC MOSFET Loss | BE8: Shunt Loss
A9: Design | B9: Input Value | C9: Units | D9: Description | G9: 0 | H9: =Vin | I9: =MODE | J9: 0 | K9: =Iout*G9/100/Number_of_Phases | L9: =Vout*K9/(Vin*Efficiency) | M9: =(Vout+(Rdson2+Rs+Rdcr)*K9)/(Vin+(Rs+Rdson2-Rdson1)*K9) | N9: =(Vin-(Rdson1+Rdcr)*K9-Vout)*M9/(Fsw*Lf) | O9: =K9+N9/2 | P9: =K9-N9/2 | Q9: =IF(MIN(Vin, -P9/(Coss_Q1+Coss_Q2)*0.00000002)<0, 0, MIN(Vin, -P9/(Coss_Q1+Coss_Q2)*0.00000002)) | R9: =SQRT(K9^2+(N9^2)/12) | S9: =R9^2*Rdcr | T9: =Core_Loss_Ch1 | U9: =(T9+S9*(1+Ltc*(Ta-25)))/(1-S9*Ltc*ThetaCa) | V9: =N9/SQRT(12) | W9: =RCoutEsr*V9^2 | X9: =W9 | Y9: =SQRT(M9*(1-M9))*SQRT(K9^2+(N9^2)/12) | Z9: =RCinEsr*Y9^2 | AA9: =Z9 | AB9: =SQRT(M9)*SQRT(K9^2+(N9^2)/12) | AC9: =Rdson1*AB9^2 | AD9: =(Vin*K9/2)*Fsw*(Tr_buck+Tf_buck) | AE9: =(0.5*Coss_Q1*(Vin-Q9)^2-0.5*Coss_Q2*(Vin-Q9)^2+(Qoss_Q2*(Vin-Q9)/Vin)*Vin)*Fsw | AF9: =IF(K9>N9/2,0,ABS(K9-N9/2)*Vsd_Q1*Deadtime*Fsw) | AG9: =(AF9+AE9+AD9+AC9*(1+RdsonTopTc*Ta-RdsonTopTc*25))/(1-AC9*RdsonTopTc*ThetaJA_Q1) | AH9: =SQRT((1-M9))*SQRT(K9^2+(N9^2)/12) | AI9: =Rdson2*AH9^2 | AJ9: =IF(K9<N9/2,Deadtime*Fsw*IF(VfdSky_Q2>0,0,Vsd_Q2)*(K9+N9/2),2*Deadtime*Fsw*IF(VfdSky_Q2>0,0,Vsd_Q2)*K9) | AK9: =(AJ9+AI9*(1+RdsonBotTc*Ta-RdsonBotTc*25))/(1-AI9*RdsonBotTc*ThetaJA_Q2) | AL9: =2*Deadtime*Fsw*IF(VfdSky_Q2>0,VfdSky_Q2,Vsd_Q2)*K9 | AM9: =IF(QrrSky_Q2>0,QrrSky_Q2,Qrr_Q2*K9/(Iout/Number_of_Phases))*Fsw*Vin | AN9: =Rs*R9^2 | AO9: =Iq*Vin | AP9: =IF(Ext_VCC=1, (Qg_Q1+Qg_Q2)*Fsw*VCC, (Qg_Q1+Qg_Q2)*Fsw*Vin) | AQ9: =(Vin-VCC)*Fsw*(Qg_Q1+Qg_Q2)+(RdsonDRT+RdsonDRT2)*Fsw*Qg_Q1*VCC/(RdsonDRT+2*Rgate1+RdsonDRT2)+(RdsonDRB+RdsonDRB2)*Fsw*Qg_Q2*VCC/(RdsonDRB+2*Rgate2+RdsonDRB2) | AR9: =(Qg_Q1+Qg_Q2)*Fsw*(Vin-VCC) | AS9: =SUM(AO9:AP9) | AT9: =SUM(U9,X9,AA9,AG9,AK9,AL9,AM9,AS9,AN9) | AU9: =Vout*K9 | AV9: =AU9/(AU9+AT9) | AW9: =ThetaJA_Q1*BC9 | AX9: =ThetaJA_Q2*BD9 | AZ9: =AV9*100 | BA9: =U9 | BB9: =AG9+AK9+AM9 | BC9: =AG9+AM9*0.66 | BD9: =AK9+AM9*0.33 | BE9: =AN9
